[2024-06-06T16:24:51.213+0000] {local_task_job_runner.py:120} INFO - ::group::Pre task execution logs
[2024-06-06T16:24:51.234+0000] {taskinstance.py:2076} INFO - Dependencies all met for dep_context=non-requeueable deps ti=<TaskInstance: weather_dag.extract_weather_data scheduled__2024-06-05T00:00:00+00:00 [queued]>
[2024-06-06T16:24:51.245+0000] {taskinstance.py:2076} INFO - Dependencies all met for dep_context=requeueable deps ti=<TaskInstance: weather_dag.extract_weather_data scheduled__2024-06-05T00:00:00+00:00 [queued]>
[2024-06-06T16:24:51.246+0000] {taskinstance.py:2306} INFO - Starting attempt 1 of 4
[2024-06-06T16:24:51.262+0000] {taskinstance.py:2330} INFO - Executing <Task(SimpleHttpOperator): extract_weather_data> on 2024-06-05 00:00:00+00:00
[2024-06-06T16:24:51.273+0000] {standard_task_runner.py:90} INFO - Running: ['***', 'tasks', 'run', 'weather_dag', 'extract_weather_data', 'scheduled__2024-06-05T00:00:00+00:00', '--job-id', '8', '--raw', '--subdir', 'DAGS_FOLDER/weather_dag.py', '--cfg-path', '/tmp/tmpl6war160']
[2024-06-06T16:24:51.272+0000] {warnings.py:110} WARNING - /home/***/.local/lib/python3.12/site-packages/***/task/task_runner/standard_task_runner.py:61: DeprecationWarning: This process (pid=1164) is multi-threaded, use of fork() may lead to deadlocks in the child.
  pid = os.fork()

[2024-06-06T16:24:51.274+0000] {standard_task_runner.py:91} INFO - Job 8: Subtask extract_weather_data
[2024-06-06T16:24:51.275+0000] {standard_task_runner.py:63} INFO - Started process 1173 to run task
[2024-06-06T16:24:51.391+0000] {task_command.py:426} INFO - Running <TaskInstance: weather_dag.extract_weather_data scheduled__2024-06-05T00:00:00+00:00 [running]> on host 918bc5ab046e
[2024-06-06T16:24:51.568+0000] {taskinstance.py:2648} INFO - Exporting env vars: AIRFLOW_CTX_DAG_EMAIL='eajavon08@gmail.com' AIRFLOW_CTX_DAG_OWNER='***' AIRFLOW_CTX_DAG_ID='weather_dag' AIRFLOW_CTX_TASK_ID='extract_weather_data' AIRFLOW_CTX_EXECUTION_DATE='2024-06-05T00:00:00+00:00' AIRFLOW_CTX_TRY_NUMBER='1' AIRFLOW_CTX_DAG_RUN_ID='scheduled__2024-06-05T00:00:00+00:00'
[2024-06-06T16:24:51.572+0000] {taskinstance.py:430} INFO - ::endgroup::
[2024-06-06T16:24:51.573+0000] {http.py:169} INFO - Calling HTTP method
[2024-06-06T16:24:51.583+0000] {base.py:84} INFO - Using connection ID 'weathermap_api' for task execution.
[2024-06-06T16:24:51.596+0000] {base.py:84} INFO - Using connection ID 'weathermap_api' for task execution.
[2024-06-06T16:24:53.866+0000] {http.py:208} INFO - {"coord":{"lon":-122.6762,"lat":45.5234},"weather":[{"id":801,"main":"Clouds","description":"few clouds","icon":"02d"}],"base":"stations","main":{"temp":289.59,"feels_like":289.01,"temp_min":287.77,"temp_max":292.01,"pressure":1019,"humidity":66},"visibility":10000,"wind":{"speed":2.06,"deg":320},"clouds":{"all":20},"dt":1717690800,"sys":{"type":2,"id":2008548,"country":"US","sunrise":1717676575,"sunset":1717732583},"timezone":-25200,"id":5746545,"name":"Portland","cod":200}
[2024-06-06T16:24:53.868+0000] {taskinstance.py:441} INFO - ::group::Post task execution logs
[2024-06-06T16:24:53.869+0000] {taskinstance.py:2905} ERROR - Task failed with exception
Traceback (most recent call last):
  File "/home/airflow/.local/lib/python3.12/site-packages/airflow/models/taskinstance.py", line 465, in _execute_task
    result = _execute_callable(context=context, **execute_callable_kwargs)
             ^^^^^^^^^^^^^^^^^^^^^^^^^^^^^^^^^^^^^^^^^^^^^^^^^^^^^^^^^^^^^
  File "/home/airflow/.local/lib/python3.12/site-packages/airflow/models/taskinstance.py", line 432, in _execute_callable
    return execute_callable(context=context, **execute_callable_kwargs)
           ^^^^^^^^^^^^^^^^^^^^^^^^^^^^^^^^^^^^^^^^^^^^^^^^^^^^^^^^^^^^
  File "/home/airflow/.local/lib/python3.12/site-packages/airflow/models/baseoperator.py", line 400, in wrapper
    return func(self, *args, **kwargs)
           ^^^^^^^^^^^^^^^^^^^^^^^^^^^
  File "/home/airflow/.local/lib/python3.12/site-packages/airflow/providers/http/operators/http.py", line 166, in execute
    return self.execute_sync(context=context)
           ^^^^^^^^^^^^^^^^^^^^^^^^^^^^^^^^^^
  File "/home/airflow/.local/lib/python3.12/site-packages/airflow/providers/http/operators/http.py", line 172, in execute_sync
    return self.process_response(context=context, response=response)
           ^^^^^^^^^^^^^^^^^^^^^^^^^^^^^^^^^^^^^^^^^^^^^^^^^^^^^^^^^
  File "/home/airflow/.local/lib/python3.12/site-packages/airflow/providers/http/operators/http.py", line 215, in process_response
    return self.response_filter(response, **kwargs)
           ^^^^^^^^^^^^^^^^^^^^^^^^^^^^^^^^^^^^^^^^
  File "/opt/airflow/dags/weather_dag.py", line 39, in <lambda>
    response_filter = lambda r: json.load(r.text),
                                ^^^^^^^^^^^^^^^^^
  File "/usr/local/lib/python3.12/json/__init__.py", line 293, in load
    return loads(fp.read(),
                 ^^^^^^^
AttributeError: 'str' object has no attribute 'read'
[2024-06-06T16:24:53.892+0000] {taskinstance.py:1206} INFO - Marking task as UP_FOR_RETRY. dag_id=weather_dag, task_id=extract_weather_data, run_id=scheduled__2024-06-05T00:00:00+00:00, execution_date=20240605T000000, start_date=20240606T162451, end_date=20240606T162453
[2024-06-06T16:24:53.912+0000] {standard_task_runner.py:110} ERROR - Failed to execute job 8 for task extract_weather_data ('str' object has no attribute 'read'; 1173)
[2024-06-06T16:24:53.942+0000] {local_task_job_runner.py:240} INFO - Task exited with return code 1
[2024-06-06T16:24:53.958+0000] {local_task_job_runner.py:222} INFO - ::endgroup::
